Workbook
Name _1: #REF!
Name M: #REF!

Sheet Info
A3: Client : | C3: Forest Car Company Ltd
A4: Year-end : | E4: PYE :
A5: From : | C5: 44783 | E5: NA
A6: To : | C6: 45260 | E6: NA
A8: Prepared By : | C8: Aratee
A9: Date : | C9: 45343
A11: Reviewed By : | C11: Mitesh
A12: Date : | C12: 45352
A14: Nature of business : | C14: Sale of used cars and light motor vehicles

Sheet Notes
B2: Client : | C2: =Info!C3 -> Forest Car Company Ltd | D2: Prepared by : | E2: =Info!C8 -> Aratee
B3: Year end : | C3: =Info!C6 -> 45260 | D3: Reviewed by : | E3: =Info!C11 -> Mitesh
B5: Notes and observations
B7: Sr. No | C7: Particulars | D7: Hyperlink | E7: Your remarks
B8: [A] | C8: GENERAL
B10: 1 | C10: Approach
C11: Accounts have been prepared based on VAT return record which includes sales, purchase and expense. We have matched bank with trade creditors and trade debtors and booked additional purchase, expense and sales from bank. We have passed necessary journal entries to prepare draft account. Please confirm.
C13: Current year is first year of business organisation, Paid up capital of 100 No. of shares price of £1 each introduce through DCA.
C15: Current year we have estimate expense Telephone £900. Please confirm.
B17: [B] | C17: BALANCE SHEET ITEMS
B19: =+B10+1 -> 2 | C19: Fixed Assets
B21: a) | C21: Intangible
D22: Fixed Assets - Intangible
B24: b) | C24: Tangible
C26: Fixtures & Fittings | D26: F2 - Tangible FA
C27: Current year there is addition of £599. We have calculated depreciation at 20% RBM. Please Confirm. | D27: F4 - FAR
C29: Computer Equipment | D29: Reallocations
C30: Current year there is addition of £1,653. We have calculated depreciation at 20% RBM. Please Confirm.
B32: =+B19+1 -> 3 | C32: Stock
C33: We have booked closing stock of £44,938 as per stock sheet. | D33: C1 - Stock
B35: =+B32+1 -> 4 | C35: Debtors
C36: At the end of the year, balance is £5,200. | D36: C2-1 - Trade debtors
B38: 5 | C38: Other debtors- (TAXcal code -4420)
D39: C2-2 - Other debtors
B42: =B38+1 -> 6 | C42: Other debtors- inter co. (TAXcal code -4423)
D43: Other Debtors - Inter company
B49: =B42+1 -> 7 | C49: Other debtors- CIS. (TAXcal code -4424)
D50: C2-6 - CIS
B51: =+B35+1 -> 5 | C51: Bank and cash
C52: Barclays Bank A/c. No.: 30470120
C53: At the end of the year, balance is £44,032. It matches with the closing bank statement.
C55: Barclays Bank A/c. No.: 50237620
C56: At the end of the year, balance is £50,000. It matches with the closing bank statement.
C58: Cash
C59: At the end of the year, balance is £1,022. | D59: C3 - Bank & Cash
C60: We have adjusted following through cash :- -Trade Creditors £68,455 adjusted. -Trade Debtors £71,072 adjusted. - Wages £630 paid through cash. - Cash £13,784 introduce through DCA.
C61: Please confirm.
B63: =+B51+1 -> 6 | C63: VAT | D63: C4-2 - VAT
C64: At the end of the year there is VAT payable of £2,862. Please confirm. | D64: VAT Rec
B66: =+B63+1 -> 7 | C66: Prepayments
...

Sheet Input Summary
A1: Client: | B1: =Info!C3 -> Forest Car Company Ltd | F1: Prepared by: | G1: =+Info!C8 -> Aratee
A2: File No: | B2: 7033 | F2: Date : | G2: =+Info!C9 -> 45343
A3: Accounting Period: | C3: =Info!C5 -> 44783
A4: Trading Period: | C4: =Info!C6 -> 45260 | F4: Reviewed by: | G4: =+Info!C11 -> Mitesh
F5: Date : | G5: =+Info!C12 -> 45352
B7: EXPENSE SUMMARY
A9: Sr No | B9: VAT Ref | C9: Date | D9: Particulars | E9: IRIS | F9: Net | G9: Vat | H9: Gross
A11: 19 | B11: VP FEB 23-34 | C11: 44901 | D11: A BAUID | E11: 27 | F11: 2000 | G11: 0 | H11: 2000 | I11: =VLOOKUP($E11,ETB!$B$66:$C$674,2,0) -> Purchases
A12: 74 | B12: VP QE MAY 23/22 | C12: 44994 | D12: A CARPENTER | E12: 27 | F12: 2500 | G12: 0 | H12: 2500 | I12: =VLOOKUP($E12,ETB!$B$66:$C$674,2,0) -> Purchases
A13: 187 | B13: VP QE NOV 23/21 | C13: 45170 | D13: A NORTON | E13: 27 | F13: 900 | G13: 0 | H13: 900 | I13: =VLOOKUP($E13,ETB!$B$66:$C$674,2,0) -> Purchases
A14: 3 | B14: VP FEB 23-23 | C14: 44872 | D14: ABDUL ALI | E14: 27 | F14: 3500 | G14: 0 | H14: 3500 | I14: =VLOOKUP($E14,ETB!$B$66:$C$674,2,0) -> Purchases
A15: 40 | B15: STOCK SHEET FEB 23 | C15: 44942 | D15: ADS | E15: 27 | F15: 3500 | G15: 0 | H15: 3500 | I15: =VLOOKUP($E15,ETB!$B$66:$C$674,2,0) -> Purchases
A16: 43 | B16: STOCK SHEET FEB 23 | C16: 44943 | D16: ADS | E16: 27 | F16: 1700 | G16: 0 | H16: 1700 | I16: =VLOOKUP($E16,ETB!$B$66:$C$674,2,0) -> Purchases
A17: 56 | B17: STOCK SHEET FEB 23 | C17: 44969 | D17: ADS | E17: 27 | F17: 300 | G17: 0 | H17: 300 | I17: =VLOOKUP($E17,ETB!$B$66:$C$674,2,0) -> Purchases
A18: 231 | B18: VP QE NOV 23/74 | C18: 45170 | D18: ADS | E18: 27 | F18: 1600 | G18: 0 | H18: 1600 | I18: =VLOOKUP($E18,ETB!$B$66:$C$674,2,0) -> Purchases
A19: 215 | B19: VP QE NOV 23/56 | C19: 45183 | D19: AGNES WALSH | E19: 27 | F19: 2350 | G19: 0 | H19: 2350 | I19: =VLOOKUP($E19,ETB!$B$66:$C$674,2,0) -> Purchases
A20: 144 | B20: VP QE AUG 23/41 | C20: 45079 | D20: ALAN DAVIS | E20: 27 | F20: 800 | G20: 0 | H20: 800 | I20: =VLOOKUP($E20,ETB!$B$66:$C$674,2,0) -> Purchases
A21: 217 | B21: VP QE NOV 23/59 | C21: 45177 | D21: ANDREW COOKE | E21: 27 | F21: 3900 | G21: 0 | H21: 3900 | I21: =VLOOKUP($E21,ETB!$B$66:$C$674,2,0) -> Purchases
A22: 1 | B22: VP FEB 23-11 | C22: 44870 | D22: B BROWN | E22: 27 | F22: 1500 | G22: 0 | H22: 1500 | I22: =VLOOKUP($E22,ETB!$B$66:$C$674,2,0) -> Purchases
... A254: 204 | B254: VP QE NOV 23/40 | C254: 45174 | D254: ZORAN REPAS | E254: 27 | F254: 2400 | G254: 0 | H254: 2400 | I254: =VLOOKUP($E254,ETB!$B$66:$C$674,2,0) -> Purchases
E256: 27 Total | F256: =SUBTOTAL(9,F11:F254) -> 532927.8 | G256: =SUBTOTAL(9,G11:G254) -> 0 | H256: =SUBTOTAL(9,H11:H254) -> 532927.8
A258: 1406 | B258: 1218 | C258: 45226 | D258: AGS WINDSCREEN | E258: 54 | F258: 630 | G258: 126 | H258: 756 | I258: =VLOOKUP($E258,ETB!$B$66:$C$674,2,0) -> Direct cost
A259: 1041 | B259: 834 | C259: 45110 | D259: AMAZON | E259: 54 | F259: 2.78 | G259: 0.55 | H259: 3.33 | I259: =VLOOKUP($E259,ETB!$B$66:$C$674,2,0) -> Direct cost
A260: 1042 | B260: 835 | C260: 45084 | D260: AMAZON | E260: 54 | F260: 15.53 | G260: 3.1 | H260: 18.63 | I260: =VLOOKUP($E260,ETB!$B$66:$C$674,2,0) -> Direct cost
A261: 1043 | B261: 836 | C261: 45104 | D261: AMAZON | E261: 54 | F261: 18.95 | G261: 3.79 | H261: 22.74 | I261: =VLOOKUP($E261,ETB!$B$66:$C$674,2,0) -> Direct cost
A262: 1044 | B262: 837 | C262: 45093 | D262: AMAZON | E262: 54 | F262: 26.63 | G262: 5.32 | H262: 31.95 | I262: =VLOOKUP($E262,ETB!$B$66:$C$674,2,0) -> Direct cost
A263: 1045 | B263: 838 | C263: 45096 | D263: AMAZON | E263: 54 | F263: 2.74 | G263: 0.55 | H263: 3.29 | I263: =VLOOKUP($E263,ETB!$B$66:$C$674,2,0) -> Direct cost
A264: 1046 | B264: 839 | C264: 45118 | D264: AMAZON | E264: 54 | F264: 12.49 | G264: 2.5 | H264: 14.99 | I264: =VLOOKUP($E264,ETB!$B$66:$C$674,2,0) -> Direct cost
A265: 1047 | B265: 840 | C265: 45093 | D265: AMAZON | E265: 54 | F265: 23.28 | G265: 4.66 | H265: 27.94 | I265: =VLOOKUP($E265,ETB!$B$66:$C$674,2,0) -> Direct cost
A266: 1048 | B266: 841 | C266: 45125 | D266: AMAZON | E266: 54 | F266: 13.33 | G266: 2.66 | H266: 15.99 | I266: =VLOOKUP($E266,ETB!$B$66:$C$674,2,0) -> Direct cost
A267: 1049 | B267: 842 | C267: 45125 | D267: AMAZON | E267: 54 | F267: 7.79 | G267: 1.56 | H267: 9.35 | I267: =VLOOKUP($E267,ETB!$B$66:$C$674,2,0) -> Direct cost
A268: 1050 | B268: 843 | C268: 45125 | D268: AMAZON | E268: 54 | F268: 5.58 | G268: 1.11 | H268: 6.69 | I268: =VLOOKUP($E268,ETB!$B$66:$C$674,2,0) -> Direct cost
A269: 1051 | B269: 844 | C269: 45159 | D269: AMAZON | E269: 54 | F269: 65.38 | G269: 13.07 | H269: 78.45 | I269: =VLOOKUP($E269,ETB!$B$66:$C$674,2,0) -> Direct cost
... A376: 1467 | B376: 1280 | C376: 45236 | D376: DVLA | E376: 54 | F376: 25.37 | G376: 0 | H376: 25.37 | I376: =VLOOKUP($E376,ETB!$B$66:$C$674,2,0) -> Direct cost
A377: 689 | B377: x` | C377: 45019 | D377: DVLA | E377: 54 | F377: 25.37 | G377: 0 | H377: 25.37 | I377: =VLOOKUP($E377,ETB!$B$66:$C$674,2,0) -> Direct cost
A378: 310 | B378: 67 | C378: 44945 | D378: EBAY | E378: 54 | F378: 112.92 | G378: 22.58 | H378: 135.5 | I378: =VLOOKUP($E378,ETB!$B$66:$C$674,2,0) -> Direct cost
A379: 311 | B379: 70 | C379: 44927 | D379: EBAY | E379: 54 | F379: 13.9 | G379: 0 | H379: 13.9 | I379: =VLOOKUP($E379,ETB!$B$66:$C$674,2,0) -> Direct cost
A380: 312 | B380: 71 | C380: 44927 | D380: EBAY | E380: 54 | F380: 39.95 | G380: 0 | H380: 39.95 | I380: =VLOOKUP($E380,ETB!$B$66:$C$674,2,0) -> Direct cost
A381: 313 | B381: 72 | C381: 44972 | D381: EBAY | E381: 54 | F381: 40.62 | G381: 8.12 | H381: 48.74 | I381: =VLOOKUP($E381,ETB!$B$66:$C$674,2,0) -> Direct cost
A382: 314 | B382: 74 | C382: 44966 | D382: EBAY | E382: 54 | F382: 26.83 | G382: 5.36 | H382: 32.19 | I382: =VLOOKUP($E382,ETB!$B$66:$C$674,2,0) -> Direct cost
...

Sheet BRS Barclays Bank Ac -30470120
A1: Client Name : | C1: =Info!C3 -> Forest Car Company Ltd | E1: Prepared by : | G1: =+Info!C8 -> Aratee
A2: File No : | C2: 7033 | D2: =+E8&"R" -> 692R | E2: Date : | G2: =+Info!C9 -> 45343
A4: A/C Holder Name: | C4: =C1 -> Forest Car Company Ltd | E4: Reviewed by : | G4: =+Info!C11 -> Mitesh
A5: Bank Name : | C5: Barclays Bank | E5: Date : | G5: =+Info!C12 -> 45352
A6: Account No. : | C6: 30470120
A7: =C5& " A/c # "&C6 -> Barclays Bank A/c # 30470120
A8: Year End : | E8: 692
A9: Start : | B9: =Info!C5 -> 44783
A10: End : | B10: =Info!C6 -> 45260
B13: BANK RECONCILIATION | E13: =B10 -> 45260
D15: Page No. | E15: Date | F15: Amount | G15: Ref
B16: Closing Balance as per Bank Statement No | E16: =B10 -> 45260 | F16: ='C3-1 - Bank 1'!G18 -> 44032.43 | G16: H / 3 / 2
B18: DETAILS OF OUTSTANDING CHEQUES | F18: =E26 -> 0
B20: Date | C20: Particulars | D20: Cheque No. | E20: Amount (£) | G20: IRIS CODE
C26: TOTAL | E26: =SUBTOTAL(9,E21:E24) -> 0
B28: Closing Balance as per Accounts | E28: =E13 -> 45260 | F28: =F16-F18 -> 44032.43
B35: Bank Book Details
B37: Opening Balance as per Accounts | E37: =B9 -> 44783 | F37: ='Barclays Bank Ac -30470120'!H13 -> 0 | G37: H / 3 / 3
B38: ADJUSTMENTS IF ANY
A40: ADD: | B40: RECEIPTS | F40: ='Barclays Bank Ac -30470120'!G1708 -> 598113.09
A42: LESS: | B42: PAYMENTS | F42: ='Barclays Bank Ac -30470120'!F1708 -> 554080.66
B45: CLOSING BALANCE AS PER ACCOUNTS | E45: =B10 -> 45260 | F45: =F37+F40-F42 -> 44032.43 | G45: H / 3 / 2
D47: Difference | F47: =F28-F45 -> 1.1641532e-10

Sheet Barclays Bank Ac -30470120
A1: Client Name : | C1: =Info!C3 -> Forest Car Company Ltd | E1: Prepared by: | G1: =+Info!C8 -> Aratee
A2: File No. : | C2: =+'BRS Barclays Bank Ac -30470120'!C2 -> 7033 | D2: =+E8 -> 692 | E2: Date: | G2: =+Info!C9 -> 45343
A4: A/C Holder Name: | C4: =+'BRS Barclays Bank Ac -30470120'!C4 -> Forest Car Company Ltd | E4: Reviewed by: | G4: =+Info!C11 -> Mitesh
A5: Bank Name : | C5: =+'BRS Barclays Bank Ac -30470120'!C5 -> Barclays Bank | E5: Date: | G5: =+Info!C12 -> 45352
A6: Account No. : | C6: =+'BRS Barclays Bank Ac -30470120'!C6 -> 30470120
A7: =C5& " A/c # "&C6 -> Barclays Bank A/c # 30470120
A8: Period Start : | C8: =Info!C5 -> 44783 | E8: =+'BRS Barclays Bank Ac -30470120'!E8 -> 692
A9: Period End : | C9: =Info!C6 -> 45260
A11: Sr No | B11: Date | D11: Particulars | E11: IRIS | F11: Payments | G11: Receipts | H11: Balance
B13: =+C8 -> 44783 | D13: OPENING BALANCE | H13: 0
A14: 1 | B14: 44882 | C14: Credit | D14: Account Fee Refund Gadbrook Park | E14: 378 | G14: 8 | H14: =+H13+G14-F14 -> 8
A15: 2 | B15: 44890 | C15: Funds Transfer | D15: 203698 93272893 Dl Ft | E15: 727 | G15: 7000 | H15: =+H14+G15-F15 -> 7008
A16: 3 | B16: 44894 | C16: Debit | D16: Ebay O*11-09399-09 On 28 Nov Bdc | E16: 54 | F16: 10.95 | H16: =+H15+G16-F16 -> 6997.05
A17: 4 | B17: 44900 | C17: Counter Credit | D17: M Stacey Cream Mini Deposit Bg | E17: 586.1 | G17: 250 | H17: =+H16+G17-F17 -> 7247.05
A18: 5 | B18: 44900 | C18: Counter Credit | D18: Marquel Edwards Car Vauxhall Adam Bgc Lm63RTu | E18: 586 | G18: 1400 | H18: =+H17+G18-F18 -> 8647.05
A19: 6 | B19: 44900 | C19: Counter Credit | D19: Marquel Edwards Lm63Rtu Bgc | E19: 586 | G19: 2500 | H19: =+H18+G19-F19 -> 11147.05
A20: 7 | B20: 44901 | C20: Counter Credit | D20: Misha Haycock Mt10Fnf Bgc | E20: 586 | G20: 1989 | H20: =+H19+G20-F20 -> 13136.05
A21: 8 | B21: 44901 | C21: Counter Credit | D21: Rutter Paul Chloe Car Bgc | E21: 586 | G21: 1500 | H21: =+H20+G21-F21 -> 14636.05
A22: 9 | B22: 44901 | C22: Funds Transfer | D22: Custom Cars Ltd Ag08Gzm Ft | E22: 737 | F22: 148 | H22: =+H21+G22-F22 -> 14488.05
A23: 10 | B23: 44901 | C23: Funds Transfer | D23: Redcorn Ltd Car Ft | E23: 737 | F23: 1000 | H23: =+H22+G23-F23 -> 13488.05
A24: 11 | B24: 44901 | C24: Funds Transfer | D24: Redcorn Ltd Car Ft | E24: 737 | F24: 800 | H24: =+H23+G24-F24 -> 12688.05
A25: 12 | B25: 44902 | C25: Counter Credit | D25: Charlie Loughbridg Mk58 Pke Bgc | E25: 586 | G25: 3700 | H25: =+H24+G25-F25 -> 16388.05
A26: 13 | B26: 44902 | C26: Funds Transfer | D26: Urban Auto Invoice December Ft | E26: 737.2 | F26: 3000 | H26: =+H25+G26-F26 -> 13388.05
A27: 14 | B27: 44904 | C27: Funds Transfer | D27: Custom Cars Ltd Ibiza Ft | E27: 737 | F27: 156 | H27: =+H26+G27-F27 -> 13232.05
A28: 15 | B28: 44904 | C28: Debit | D28: Equita Ltd On 08 Dec Bdc | E28: 280 | F28: 189 | H28: =+H27+G28-F28 -> 13043.05
A29: 16 | B29: 44908 | C29: Counter Credit | D29: Barnes Helen Jimmy Bgc | E29: 586 | G29: 250 | H29: =+H28+G29-F29 -> 13293.05
A30: 17 | B30: 44908 | C30: Debit | D30: The Lowry Hotel On 12 Dec Bdc | E30: 737 | F30: 300 | H30: =+H29+G30-F30 -> 12993.05
A31: 18 | B31: 44908 | C31: Debit | D31: Zettle_*Ali Cab On 12 Dec Bdc | E31: 266 | F31: 41.2 | H31: =+H30+G31-F31 -> 12951.85
A32: 19 | B32: 44909 | C32: Counter Credit | D32: Barnes Helen Jimmy Bgc | E32: 586 | G32: 3859 | H32: =+H31+G32-F32 -> 16810.85
A33: 20 | B33: 44909 | C33: Debit | D33: Paypal *Trainline On 12 Dec Bdc | E33: 266 | F33: 139.19 | H33: =+H32+G33-F33 -> 16671.66
A34: 21 | B34: 44911 | C34: Debit | D34: Auto Trader On 15 Dec Bdc | E34: 737 | F34: 20.7 | H34: =+H33+G34-F34 -> 16650.96
A35: 22 | B35: 44911 | C35: Debit | D35: Auto Trader On 15 Dec Bdc | E35: 737 | F35: 20.7 | H35: =+H34+G35-F35 -> 16630.26
A36: 23 | B36: 44911 | C36: Debit | D36: Auto Trader On 15 Dec Bdc | E36: 737 | F36: 34.2 | H36: =+H35+G36-F36 -> 16596.06
A37: 24 | B37: 44911 | C37: Debit | D37: Auto Trader On 15 Dec Bdc | E37: 737 | F37: 35.94 | H37: =+H36+G37-F37 -> 16560.12
A38: 25 | B38: 44911 | C38: Funds Transfer | D38: Crown Cars Invoice Ft | E38: 737 | F38: 280 | H38: =+H37+G38-F38 -> 16280.12
A39: 26 | B39: 44914 | C39: Counter Credit | D39: Jasper Ka Delivery Norfolk Bgc | E39: 668 | G39: 240 | H39: =+H38+G39-F39 -> 16520.12
A40: 27 | B40: 44914 | C40: Funds Transfer | D40: Henningsen Trading Invoice Ft | E40: 27 | F40: 2935 | H40: =+H39+G40-F40 -> 13585.12
A41: 28 | B41: 44914 | C41: Debit | D41: Land Registry Ecom On 16 Dec Bdc | E41: 290 | F41: 6 | H41: =+H40+G41-F41 -> 13579.12
A42: 29 | B42: 44914 | C42: Funds Transfer | D42: Redcorn Ltd Car Ft | E42: 737 | F42: 700 | H42: =+H41+G42-F42 -> 12879.12
A43: 30 | B43: 44915 | C43: Counter Credit | D43: Wisdom James Car Bgc Cx62Ysh | E43: 586 | G43: 550 | H43: =+H42+G43-F43 -> 13429.12
...

Sheet Index
B2: Client : | C2: =Info!C3 -> Forest Car Company Ltd | G2: Prepared by : | H2: =Info!C8 -> Aratee | I2: Date : | J2: =Info!C9 -> 45343
B3: Year end : | C3: =Info!C6 -> 45260 | G3: Reviewed by : | H3: =Info!C11 -> Mitesh | I3: Date : | J3: =Info!C12 -> 45352
B5: Index of working papers
B8: Sr. No | C8: Particulars | G8: Hyperlink
B10: 1 | C10: =+Notes!B5 -> Notes and observations | E10: a | G10: =+C10 -> Notes and observations
B12: =+B10+1 -> 2 | C12: =+'Job plan'!B5 -> Job plan | E12: a | G12: =+C12 -> Job plan | K12: r
B14: =+B12+1 -> 3 | C14: =+Queries!B5 -> Queries | E14: a | G14: =+C14 -> Queries
B16: =+B14+1 -> 4 | C16: =+'Profit & Loss'!B5 -> Profit and loss account | E16: a | G16: =+C16 -> Profit and loss account
B18: =+B16+1 -> 5 | C18: =+'Balance Sheet'!B5 -> Balance Sheet | E18: a | G18: =+C18 -> Balance Sheet
B20: =+B18+1 -> 6 | C20: =+ETB!B5 -> Extended Trial Balance (ETB) | E20: a | G20: =+C20 -> Extended Trial Balance (ETB)
B22: =+B20+1 -> 7 | C22: =+Journal!B5 -> Journals | E22: a | G22: =+C22 -> Journals
B24: =+B22+1 -> 8 | C24: =+TB!B5 -> Trial Balance | E24: a | G24: =+C24 -> Trial Balance
B26: =+B24+1 -> 9 | C26: =+'F - Fixed Assets'!B5 -> Lead Schedule - Fixed Assets | E26: r | G26: =+C26 -> Lead Schedule - Fixed Assets
B28: =+B26+1 -> 10 | C28: =+'F1 - Intangible FA'!B5 -> Fixed Assets - Intangible | E28: r | G28: =+C28 -> Fixed Assets - Intangible
B30: =+B28+1 -> 11 | C30: =+'F2 - Tangible FA'!B5 -> Fixed Assets - Tangible | E30: r | G30: =+C30 -> Fixed Assets - Tangible
B32: =+B30+1 -> 12 | C32: =+'F4 - FAR'!B5 -> Fixed asset register | E32: r | G32: =+C32 -> Fixed asset register
B34: =+B32+1 -> 13 | C34: =+'F5 - Investments'!B5 -> Investments | E34: a | G34: =+C34 -> Investments
B36: =+B34+1 -> 14 | C36: =+'C1 - Stock'!B5 -> Lead Schedule - Stock | E36: r | G36: =+C36 -> Lead Schedule - Stock
B38: =+B36+1 -> 15 | C38: =+'C2 - Debtors'!B5 -> Lead Schedule - Debtors | E38: a | G38: =+C38 -> Lead Schedule - Debtors
B40: =+B38+1 -> 16 | C40: =+'C2-1 - Trade debtors'!B5 -> Trade debtors | E40: a | G40: =+C40 -> Trade debtors
B42: =+B40+1 -> 17 | C42: =+'C2-2-1 - Other Debtors'!B5 -> Other Debtors | E42: a | G42: =+C42 -> Other Debtors
B44: =+B42+1 -> 18 | C44: =+'C2-3 - Prepayments'!B5 -> Prepayments | E44: a | G44: =+C44 -> Prepayments
B46: =+B44+1 -> 19 | C46: =+'C2-4 - Accrued Income'!B5 -> Other Debtors | E46: a | G46: =+C46 -> Other Debtors
B48: =+B46+1 -> 20 | C48: =+'C2-5 - Other debtors-Inter co.'!B5 -> Other Debtors - Inter company | E48: a | G48: =+C48 -> Other Debtors - Inter company
B50: =+B48+1 -> 21 | C50: =+'C2-6 - CIS'!B5 -> Other Debtors - CIS | E50: a | G50: =+C50 -> Other Debtors - CIS
B52: =+B50+1 -> 22 | C52: =+'C2-7 - Other debtors (3)'!B5 -> Other Debtors - 3 | E52: a | G52: =+C52 -> Other Debtors - 3
B54: =+B52+1 -> 23 | C54: =+'C3 - Bank & Cash'!B5 -> Lead Schedule - Bank and Cash in hand | E54: a | G54: =+C54 -> Lead Schedule - Bank and Cash in hand
B56: =+B54+1 -> 24 | C56: =+'C3-1 - Bank 1'!B5 -> Bank account - 1 | E56: a | G56: =+C56 -> Bank account - 1
B58: =+B56+1 -> 25 | C58: =+'C3-4 - Bank-2'!B5 -> Bank account - 2 | E58: a | G58: =+C58 -> Bank account - 2
B60: =+B58+1 -> 26 | C60: =+'C5 - Cash'!B5 -> Cash | E60: a | G60: =+C60 -> Cash
B62: =+B60+1 -> 27 | C62: =+'C4 - Creditors'!B5 -> Lead Schedule - Creditors < 1 Year | E62: a | G62: =+C62 -> Lead Schedule - Creditors < 1 Year
B64: =+B62+1 -> 28 | C64: =+'C4-1 - Trade creditors'!B5 -> Trade creditors | E64: a | G64: =+C64 -> Trade creditors
B66: =+B64+1 -> 29 | C66: =+'C2-2 - Other debtors'!B5 -> Other creditors | E66: a | G66: =+C66 -> Other creditors
B68: =+B66+1 -> 30 | C68: =+'C4-3 - CT'!B5 -> Corporation tax | E68: a | G68: =+C68 -> Corporation tax
B70: =+B68+1 -> 31 | C70: =+'C4-2 - VAT'!B5 -> VAT Liability | E70: a | G70: =+C70 -> VAT Liability
B72: =+B70+1 -> 32 | C72: =+'VAT Rec'!B5 -> VAT Reconciliation | E72: a | G72: =+C72 -> VAT Reconciliation
B74: =+B72+1 -> 33 | C74: =+'C4-4 - PAYE-NI'!B5 -> PAYE/NI Liability | E74: a | G74: =+C74 -> PAYE/NI Liability
B76: =+B74+1 -> 34 | C76: =+'C4-10 - Net wages'!B5 -> Net wages | E76: a | G76: =+C76 -> Net wages
B78: =+B76+1 -> 35 | C78: =+'C4-5 - Other creditors'!B5 -> Other creditors | E78: a | G78: =+C78 -> Other creditors
B80: =+B78+1 -> 36 | C80: =+'C4-6 - Accruals'!B5 -> Accruals | E80: a | G80: =+C80 -> Accruals
...

Sheet Barclays Bank Ac -30470120 (C)
A1: Client Name : | C1: =Info!C3 -> Forest Car Company Ltd | E1: Prepared by: | G1: =+Info!C8 -> Aratee
A2: File No. : | C2: =+'BRS Barclays Bank Ac -30470120'!C2 -> 7033 | D2: =+E8 -> 692 | E2: Date: | G2: =+Info!C9 -> 45343
A4: A/C Holder Name: | C4: =+'BRS Barclays Bank Ac -30470120'!C4 -> Forest Car Company Ltd | E4: Reviewed by: | G4: =+Info!C11 -> Mitesh
A5: Bank Name : | C5: =+'BRS Barclays Bank Ac -30470120'!C5 -> Barclays Bank | E5: Date: | G5: =+Info!C12 -> 45352
A6: Account No. : | C6: =+'BRS Barclays Bank Ac -30470120'!C6 -> 30470120
A7: =C5& " A/c # "&C6 -> Barclays Bank A/c # 30470120
A8: Period Start : | C8: =Info!C5 -> 44783 | E8: =+'BRS Barclays Bank Ac -30470120'!E8 -> 692
A9: Period End : | C9: =Info!C6 -> 45260
A11: Sr No | B11: Date | D11: Particulars | E11: IRIS | F11: Payments | G11: Receipts
A13: 421 | B13: 45041 | C13: Funds Transfer | D13: A Kalafatis Warranty 107 Red09 Ft | E13: 1 | F13: 134 | H13: =VLOOKUP($E13,ETB!$B$66:$C$674,2,0) -> Sales
A14: 428 | B14: 44949 | C14: Funds Transfer | D14: A Smith Partial Refund Min Ft | E14: 1 | F14: 160 | H14: =VLOOKUP($E14,ETB!$B$66:$C$674,2,0) -> Sales
E16: 1 Total | F16: =SUBTOTAL(9,F13:F14) -> 0 | G16: =SUBTOTAL(9,G13:G14) -> 0
A18: 1247 | B18: 45091 | C18: Funds Transfer | D18: Essex Trader Uk Lt Green C3 Ft | E18: 27 | F18: 1100 | H18: =VLOOKUP($E18,ETB!$B$66:$C$674,2,0) -> Purchases
A19: 1266 | B19: 44914 | C19: Funds Transfer | D19: Henningsen Trading Invoice Ft | E19: 27 | F19: 2935 | H19: =VLOOKUP($E19,ETB!$B$66:$C$674,2,0) -> Purchases
A20: 1439 | B20: 45187 | C20: Funds Transfer | D20: Redcorn Ltd Car B Ft | E20: 27 | F20: 3180 | H20: =VLOOKUP($E20,ETB!$B$66:$C$674,2,0) -> Purchases
A21: 1460 | B21: 45131 | C21: Funds Transfer | D21: Redcorn Ltd Car Ft | E21: 27 | F21: 700 | H21: =VLOOKUP($E21,ETB!$B$66:$C$674,2,0) -> Purchases
A22: 1473 | B22: 45111 | C22: Funds Transfer | D22: Redcorn Ltd Car J Ft | E22: 27 | F22: 2800 | H22: =VLOOKUP($E22,ETB!$B$66:$C$674,2,0) -> Purchases
A23: 1478 | B23: 45250 | C23: Funds Transfer | D23: Redcorn Ltd Car J Ft | E23: 27 | F23: 5074 | H23: =VLOOKUP($E23,ETB!$B$66:$C$674,2,0) -> Purchases
A24: 1479 | B24: 45254 | C24: Funds Transfer | D24: Redcorn Ltd Car J Ft | E24: 27 | F24: 3308 | H24: =VLOOKUP($E24,ETB!$B$66:$C$674,2,0) -> Purchases
A25: 1496 | B25: 45208 | C25: Funds Transfer | D25: Redcorn Ltd Car P Ft | E25: 27 | F25: 2680 | H25: =VLOOKUP($E25,ETB!$B$66:$C$674,2,0) -> Purchases
A26: 1497 | B26: 45113 | C26: Funds Transfer | D26: Redcorn Ltd Car R Ft | E26: 27 | F26: 1800 | H26: =VLOOKUP($E26,ETB!$B$66:$C$674,2,0) -> Purchases
A27: 1509 | B27: 45258 | C27: Funds Transfer | D27: Redcorn Ltd Car U Ft | E27: 27 | F27: 660 | H27: =VLOOKUP($E27,ETB!$B$66:$C$674,2,0) -> Purchases
A28: 1511 | B28: 45233 | C28: Funds Transfer | D28: Redcorn Ltd Car W Ft | E28: 27 | F28: 600 | H28: =VLOOKUP($E28,ETB!$B$66:$C$674,2,0) -> Purchases
A29: 1519 | B29: 45251 | C29: Funds Transfer | D29: Redcorn Ltd Car Y Ft | E29: 27 | F29: 3080 | H29: =VLOOKUP($E29,ETB!$B$66:$C$674,2,0) -> Purchases
A30: 1520 | B30: 45244 | C30: Funds Transfer | D30: Redcorn Ltd Car Z Ft | E30: 27 | F30: 2410 | H30: =VLOOKUP($E30,ETB!$B$66:$C$674,2,0) -> Purchases
E32: 27 Total | F32: =SUBTOTAL(9,F18:F30) -> 0 | G32: =SUBTOTAL(9,G18:G30) -> 0
A34: 422 | B34: 45194 | C34: Funds Transfer | D34: A Nazir 0012 Ft | E34: 54 | F34: 140 | H34: =VLOOKUP($E34,ETB!$B$66:$C$674,2,0) -> Direct cost
A35: 423 | B35: 45222 | C35: Funds Transfer | D35: A Nazir Ecu Fix Ft | E35: 54 | F35: 120 | H35: =VLOOKUP($E35,ETB!$B$66:$C$674,2,0) -> Direct cost
A36: 424 | B36: 45257 | C36: Funds Transfer | D36: A Nazir Electronics Ft | E36: 54 | F36: 390 | H36: =VLOOKUP($E36,ETB!$B$66:$C$674,2,0) -> Direct cost
A37: 427 | B37: 45222 | C37: Funds Transfer | D37: A Pilgrim C3 58 Scrap Ft | E37: 54 | F37: 200 | H37: =VLOOKUP($E37,ETB!$B$66:$C$674,2,0) -> Direct cost
A38: 446 | B38: 45002 | C38: Debit | D38: Allen Briggs Motor On 16 Mar Bdc | E38: 54 | F38: 133.87 | H38: =VLOOKUP($E38,ETB!$B$66:$C$674,2,0) -> Direct cost
A39: 447 | B39: 45082 | C39: Funds Transfer | D39: Altaf Nazir Map Ft | E39: 54 | F39: 400 | H39: =VLOOKUP($E39,ETB!$B$66:$C$674,2,0) -> Direct cost
A40: 448 | B40: 45184 | C40: Funds Transfer | D40: Altaf Nazir Map Ft | E40: 54 | F40: 240 | H40: =VLOOKUP($E40,ETB!$B$66:$C$674,2,0) -> Direct cost
A41: 449 | B41: 45252 | C41: Funds Transfer | D41: Altaf Nazir Map Ft | E41: 54 | F41: 280 | H41: =VLOOKUP($E41,ETB!$B$66:$C$674,2,0) -> Direct cost
A42: 457 | B42: 45051 | C42: Debit | D42: Amazon.Co.Uk*Ew8Ez On 04 May Bdc | E42: 54 | F42: 49 | H42: =VLOOKUP($E42,ETB!$B$66:$C$674,2,0) -> Direct cost
A43: 468 | B43: 45049 | C43: Debit | D43: Amznmktplace On 02 May Bdc | E43: 54 | F43: 27.95 | H43: =VLOOKUP($E43,ETB!$B$66:$C$674,2,0) -> Direct cost
A44: 469 | B44: 45049 | C44: Debit | D44: Amznmktplace On 02 May Bdc | E44: 54 | F44: 14.99 | H44: =VLOOKUP($E44,ETB!$B$66:$C$674,2,0) -> Direct cost
A45: 501 | B45: 45191 | C45: Debit | D45: Amznmktplace On 21 Sep Bdc | E45: 54 | F45: 19.99 | H45: =VLOOKUP($E45,ETB!$B$66:$C$674,2,0) -> Direct cost
... A64: 1018 | B64: 45258 | C64: Debit | D64: Ebay C 15441851672 On 28 Nov Bdc | E64: 54 | F64: 14.99 | H64: =VLOOKUP($E64,ETB!$B$66:$C$674,2,0) -> Direct cost
A65: 59 | B65: 45118 | C65: Counter Credit | D65: Ebay Commerce Uk L Ebay Microdeposit Bg | E65: 54 | G65: 0.05 | H65: =VLOOKUP($E65,ETB!$B$66:$C$674,2,0) -> Direct cost
...

Sheet Queries
B2: Client : | C2: =Info!C3 -> Forest Car Company Ltd | F2: Prepared by : | G2: =Info!C8 -> Aratee | H2: Date : | I2: =Info!C9 -> 45343
B3: Year end : | C3: =Info!C6 -> 45260 | F3: Reviewed by : | G3: =Info!C11 -> Mitesh | H3: Date : | I3: =Info!C12 -> 45352
B5: Queries
C7: 1 | D7: Need Invoice copy for booking
K14: Mitesh review pont
J16: 1 | K16: Sales sheet- always use formula/ margin/VAT | Q16: Done - VAT as it is
J17: 2 | K17: Refreshment- Where VAT consider / remoev from personal/ keep around 2400 | Q17: Done
J18: 3 | K18: DCA- BP/ BR | Q18: Done
J19: 4 | K19: Old format/ IRIS

Sheet Reallocations
B2: Client : | C2: =Info!C3 -> Forest Car Company Ltd | F2: Prepared by : | G2: =Info!C8 -> Aratee | H2: Date : | I2: =Info!C9 -> 45343
B3: Year end : | C3: =Info!C6 -> 45260 | F3: Reviewed by : | G3: =Info!C11 -> Mitesh | H3: Date : | I3: =Info!C12 -> 45352
B5: Reallocations

Sheet Job plan
B2: Client : | C2: =Info!C3 -> Forest Car Company Ltd | F2: Prepared by : | G2: =Info!C8 -> Aratee | H2: Date : | I2: =Info!C9 -> 45343
B3: Year end : | C3: =Info!C6 -> 45260 | F3: Reviewed by : | G3: =Info!C11 -> Mitesh | H3: Date : | I3: =Info!C12 -> 45352
B5: Job plan
C6: Particulars | G6: Hours

Sheet Communication
B2: Client : | C2: =Info!C3 -> Forest Car Company Ltd | F2: Prepared by : | G2: =Info!C8 -> Aratee | H2: Date : | I2: =Info!C9 -> 45343
B3: Year end : | C3: =Info!C6 -> 45260 | F3: Reviewed by : | G3: =Info!C11 -> Mitesh | H3: Date : | I3: =Info!C12 -> 45352
B5: Communication trail

Sheet Opening Bal Adj
B2: =CONCATENATE(Info!A3," ",Info!C3) -> Client : Forest Car Company Ltd | E2: Prepared by : | F2: =Info!C8 -> Aratee | H2: Date : | I2: =Info!C9 -> 45343
B3: =Info!A4 -> Year-end : | E3: Reviewed by : | F3: =Info!C11 -> Mitesh | H3: Date : | I3: =Info!C12 -> 45352
B4: =Info!C6 -> 45260
B6: Opening Balance Adjustments
E8: As per XERO | H8: As per Final Accounts | K8: Difference in opening entries | N8: Opening Balance Diifference already adjusted | Q8: Opening balance difference
B9: Details | C9: TaxCalc Code | E9: Dr £ | F9: Cr £ | H9: Dr £ | I9: Cr £ | K9: Dr £ | L9: Cr £ | N9: Dr £ | O9: Cr £ | Q9: Dr £ | R9: Cr £
K11: =MAX(((H11-E11)-(I11-F11)),0) -> 0 | L11: =MAX(((I11-F11)-(H11-E11)),0) -> 0 | N11: 0 | O11: 0 | Q11: =MAX(((K11-L11)-(N11-O11)),0) -> 0 | R11: =MAX(((L11-K11)-(O11-N11)),0) -> 0
K12: =MAX(((H12-E12)-(I12-F12)),0) -> 0 | L12: =MAX(((I12-F12)-(H12-E12)),0) -> 0 | N12: 0 | O12: 0 | Q12: =MAX(((K12-L12)-(N12-O12)),0) -> 0 | R12: =MAX(((L12-K12)-(O12-N12)),0) -> 0
K13: =MAX(((H13-E13)-(I13-F13)),0) -> 0 | L13: =MAX(((I13-F13)-(H13-E13)),0) -> 0 | N13: 0 | O13: 0 | Q13: =MAX(((K13-L13)-(N13-O13)),0) -> 0 | R13: =MAX(((L13-K13)-(O13-N13)),0) -> 0
K14: =MAX(((H14-E14)-(I14-F14)),0) -> 0 | L14: =MAX(((I14-F14)-(H14-E14)),0) -> 0 | N14: 0 | O14: 0 | Q14: =MAX(((K14-L14)-(N14-O14)),0) -> 0 | R14: =MAX(((L14-K14)-(O14-N14)),0) -> 0
K15: =MAX(((H15-E15)-(I15-F15)),0) -> 0 | L15: =MAX(((I15-F15)-(H15-E15)),0) -> 0 | N15: 0 | O15: 0 | Q15: =MAX(((K15-L15)-(N15-O15)),0) -> 0 | R15: =MAX(((L15-K15)-(O15-N15)),0) -> 0
K16: =MAX(((H16-E16)-(I16-F16)),0) -> 0 | L16: =MAX(((I16-F16)-(H16-E16)),0) -> 0 | N16: 0 | O16: 0 | Q16: =MAX(((K16-L16)-(N16-O16)),0) -> 0 | R16: =MAX(((L16-K16)-(O16-N16)),0) -> 0
K17: =MAX(((H17-E17)-(I17-F17)),0) -> 0 | L17: =MAX(((I17-F17)-(H17-E17)),0) -> 0 | N17: 0 | O17: 0 | Q17: =MAX(((K17-L17)-(N17-O17)),0) -> 0 | R17: =MAX(((L17-K17)-(O17-N17)),0) -> 0
K18: =MAX(((H18-E18)-(I18-F18)),0) -> 0 | L18: =MAX(((I18-F18)-(H18-E18)),0) -> 0 | N18: 0 | O18: 0 | Q18: =MAX(((K18-L18)-(N18-O18)),0) -> 0 | R18: =MAX(((L18-K18)-(O18-N18)),0) -> 0
K19: =MAX(((H19-E19)-(I19-F19)),0) -> 0 | L19: =MAX(((I19-F19)-(H19-E19)),0) -> 0 | N19: 0 | O19: 0 | Q19: =MAX(((K19-L19)-(N19-O19)),0) -> 0 | R19: =MAX(((L19-K19)-(O19-N19)),0) -> 0
K20: =MAX(((H20-E20)-(I20-F20)),0) -> 0 | L20: =MAX(((I20-F20)-(H20-E20)),0) -> 0 | N20: 0 | O20: 0 | Q20: =MAX(((K20-L20)-(N20-O20)),0) -> 0 | R20: =MAX(((L20-K20)-(O20-N20)),0) -> 0
K21: =MAX(((H21-E21)-(I21-F21)),0) -> 0 | L21: =MAX(((I21-F21)-(H21-E21)),0) -> 0 | N21: 0 | O21: 0 | Q21: =MAX(((K21-L21)-(N21-O21)),0) -> 0 | R21: =MAX(((L21-K21)-(O21-N21)),0) -> 0
K22: =MAX(((H22-E22)-(I22-F22)),0) -> 0 | L22: =MAX(((I22-F22)-(H22-E22)),0) -> 0 | N22: 0 | O22: 0 | Q22: =MAX(((K22-L22)-(N22-O22)),0) -> 0 | R22: =MAX(((L22-K22)-(O22-N22)),0) -> 0
... K24: =MAX(((H24-E24)-(I24-F24)),0) -> 0 | L24: =MAX(((I24-F24)-(H24-E24)),0) -> 0 | N24: 0 | O24: 0 | Q24: =MAX(((K24-L24)-(N24-O24)),0) -> 0 | R24: =MAX(((L24-K24)-(O24-N24)),0) -> 0
K25: =MAX(((H25-E25)-(I25-F25)),0) -> 0 | L25: =MAX(((I25-F25)-(H25-E25)),0) -> 0 | N25: 0 | O25: 0 | Q25: =MAX(((K25-L25)-(N25-O25)),0) -> 0 | R25: =MAX(((L25-K25)-(O25-N25)),0) -> 0 | S25: 24200.93
K26: =MAX(((H26-E26)-(I26-F26)),0) -> 0 | L26: =MAX(((I26-F26)-(H26-E26)),0) -> 0 | N26: 0 | O26: 0 | Q26: =MAX(((K26-L26)-(N26-O26)),0) -> 0 | R26: =MAX(((L26-K26)-(O26-N26)),0) -> 0 | S26: 20169.76
L27: =E28+E29+E30+E31-H27 -> 0 | N27: 0 | O27: 0 | Q27: =MAX(((K27-L27)-(N27-O27)),0) -> 0 | R27: =MAX(((L27-K27)-(O27-N27)),0) -> 0
K28: =MAX(((H28-E28)-(I28-F28)),0) -> 0 | N28: 0 | O28: 0 | Q28: =MAX(((K28-L28)-(N28-O28)),0) -> 0 | R28: =MAX(((L28-K28)-(O28-N28)),0) -> 0
K29: =MAX(((H29-E29)-(I29-F29)),0) -> 0 | N29: 0 | O29: 0 | Q29: =MAX(((K29-L29)-(N29-O29)),0) -> 0 | R29: =MAX(((L29-K29)-(O29-N29)),0) -> 0
K30: =MAX(((H30-E30)-(I30-F30)),0) -> 0 | N30: 0 | O30: 0 | Q30: =MAX(((K30-L30)-(N30-O30)),0) -> 0 | R30: =MAX(((L30-K30)-(O30-N30)),0) -> 0
K31: =MAX(((H31-E31)-(I31-F31)),0) -> 0 | N31: 0 | O31: 0 | Q31: =MAX(((K31-L31)-(N31-O31)),0) -> 0 | R31: =MAX(((L31-K31)-(O31-N31)),0) -> 0
K32: =MAX(((H32-E32)-(I32-F32)),0) -> 0 | L32: =MAX(((I32-F32)-(H32-E32)),0) -> 0 | N32: 0 | O32: 0 | Q32: =MAX(((K32-L32)-(N32-O32)),0) -> 0 | R32: =MAX(((L32-K32)-(O32-N32)),0) -> 0
K33: =MAX(((H33-E33)-(I33-F33)),0) -> 0 | L33: =MAX(((I33-F33)-(H33-E33)),0) -> 0 | N33: 0 | O33: 0 | Q33: =MAX(((K33-L33)-(N33-O33)),0) -> 0 | R33: =MAX(((L33-K33)-(O33-N33)),0) -> 0
K34: =MAX(((H34-E34)-(I34-F34)),0) -> 0 | L34: =MAX(((I34-F34)-(H34-E34)),0) -> 0 | N34: 0 | O34: 0 | Q34: =MAX(((K34-L34)-(N34-O34)),0) -> 0 | R34: =MAX(((L34-K34)-(O34-N34)),0) -> 0
K35: =MAX(((H35-E35)-(I35-F35)),0) -> 0 | L35: =MAX(((I35-F35)-(H35-E35)),0) -> 0 | N35: 0 | O35: 0 | Q35: =MAX(((K35-L35)-(N35-O35)),0) -> 0 | R35: =MAX(((L35-K35)-(O35-N35)),0) -> 0
K36: =MAX(((H36-E36)-(I36-F36)),0) -> 0 | L36: =MAX(((I36-F36)-(H36-E36)),0) -> 0 | N36: 0 | O36: 0 | Q36: =MAX(((K36-L36)-(N36-O36)),0) -> 0 | R36: =MAX(((L36-K36)-(O36-N36)),0) -> 0
K37: =MAX(((H37-E37)-(I37-F37)),0) -> 0 | L37: =MAX(((I37-F37)-(H37-E37)),0) -> 0 | N37: 0 | O37: 0 | Q37: =MAX(((K37-L37)-(N37-O37)),0) -> 0 | R37: =MAX(((L37-K37)-(O37-N37)),0) -> 0
K38: =MAX(((H38-E38)-(I38-F38)),0) -> 0 | L38: =MAX(((I38-F38)-(H38-E38)),0) -> 0 | N38: 0 | O38: 0 | Q38: =MAX(((K38-L38)-(N38-O38)),0) -> 0 | R38: =MAX(((L38-K38)-(O38-N38)),0) -> 0
K39: =MAX(((H39-E39)-(I39-F39)),0) -> 0 | L39: =MAX(((I39-F39)-(H39-E39)),0) -> 0 | N39: 0 | O39: 0 | Q39: =MAX(((K39-L39)-(N39-O39)),0) -> 0 | R39: =MAX(((L39-K39)-(O39-N39)),0) -> 0
K40: =MAX(((H40-E40)-(I40-F40)),0) -> 0 | L40: =MAX(((I40-F40)-(H40-E40)),0) -> 0 | N40: 0 | O40: 0 | Q40: =MAX(((K40-L40)-(N40-O40)),0) -> 0 | R40: =MAX(((L40-K40)-(O40-N40)),0) -> 0
K41: =MAX(((H41-E41)-(I41-F41)),0) -> 0 | L41: =MAX(((I41-F41)-(H41-E41)),0) -> 0 | N41: 0 | O41: 0 | Q41: =MAX(((K41-L41)-(N41-O41)),0) -> 0 | R41: =MAX(((L41-K41)-(O41-N41)),0) -> 0
K42: =MAX(((H42-E42)-(I42-F42)),0) -> 0 | L42: =MAX(((I42-F42)-(H42-E42)),0) -> 0 | N42: 0 | O42: 0 | Q42: =MAX(((K42-L42)-(N42-O42)),0) -> 0 | R42: =MAX(((L42-K42)-(O42-N42)),0) -> 0
K43: =MAX(((H43-E43)-(I43-F43)),0) -> 0 | L43: =MAX(((I43-F43)-(H43-E43)),0) -> 0 | N43: 0 | O43: 0 | Q43: =MAX(((K43-L43)-(N43-O43)),0) -> 0 | R43: =MAX(((L43-K43)-(O43-N43)),0) -> 0
... K48: =MAX(((H48-E48)-(I48-F48)),0) -> 0 | L48: =MAX(((I48-F48)-(H48-E48)),0) -> 0 | N48: 0 | O48: 0 | Q48: =MAX(((K48-L48)-(N48-O48)),0) -> 0 | R48: =MAX(((L48-K48)-(O48-N48)),0) -> 0
E50: =SUM(E11:E49) -> 0 | F50: =SUM(F11:F49) -> 0 | H50: =SUM(H11:H49) -> 0 | I50: =SUM(I11:I49) -> 0 | K50: =SUM(K11:K49) -> 0 | L50: =SUM(L11:L49) -> 0 | N50: =SUM(N11:N49) -> 0 | O50: =SUM(O11:O49) -> 0 | Q50: =SUM(Q11:Q49) -> 0 | R50: =SUM(R11:R49) -> 0
...

Sheet Barclays Bank Ac 50237620
A1: Client Name : | C1: =Info!C3 -> Forest Car Company Ltd | E1: Prepared by: | G1: =+Info!C8 -> Aratee
A2: File No. : | C2: =+'BRS Barclays Bank Ac -30470120'!C2 -> 7033 | D2: =+E8 -> 692 | E2: Date: | G2: =+Info!C9 -> 45343
A4: A/C Holder Name: | C4: =+'BRS Barclays Bank Ac -30470120'!C4 -> Forest Car Company Ltd | E4: Reviewed by: | G4: =+Info!C11 -> Mitesh
A5: Bank Name : | C5: =+'BRS Barclays Bank Ac -30470120'!C5 -> Barclays Bank | E5: Date: | G5: =+Info!C12 -> 45352
A6: Account No. : | C6: =+'BRS Barclays Bank Ac -30470120'!C6 -> 30470120
A7: =C5& " A/c # "&C6 -> Barclays Bank A/c # 30470120
A8: Period Start : | C8: =Info!C5 -> 44783 | E8: =+'BRS Barclays Bank Ac -30470120'!E8 -> 692
A9: Period End : | C9: =Info!C6 -> 45260
A11: Sr No | B11: Date | D11: Particulars | E11: IRIS | F11: Payments | G11: Receipts | H11: Balance
B13: =+C8 -> 44783 | D13: OPENING BALANCE | H13: 0
A14: 1 | B14: 45232 | C14: Fund transfer | D14: 202519 30470120 MOBILE-CHANNEL FT | E14: 692 | G14: 50000 | H14: =H13-F14+G14 -> 50000
A17: Total£ | B17: 45187 | F17: =SUM(F14:F16) -> 0 | G17: =SUM(G14:G16) -> 50000 | H17: =H13+G17-F17 -> 50000

Sheet BRS Barclays Bank Ac 50237620
A1: Client Name : | C1: =Info!C3 -> Forest Car Company Ltd | E1: Prepared by : | G1: =+Info!C8 -> Aratee
A2: File No : | C2: 7033 | D2: =+E8&"R" -> 693R | E2: Date : | G2: =+Info!C9 -> 45343
A4: A/C Holder Name: | C4: =C1 -> Forest Car Company Ltd | E4: Reviewed by : | G4: =+Info!C11 -> Mitesh
A5: Bank Name : | C5: Barclays Bank | E5: Date : | G5: =+Info!C12 -> 45352
A6: Account No. : | C6: 50237620
A7: =C5& " A/c # "&C6 -> Barclays Bank A/c # 50237620
A8: Year End : | E8: 693
A9: Start : | B9: =Info!C5 -> 44783
A10: End : | B10: =Info!C6 -> 45260
B13: BANK RECONCILIATION | E13: =B10 -> 45260
D15: Page No. | E15: Date | F15: Amount | G15: Ref
B16: Closing Balance as per Bank Statement No | E16: =B10 -> 45260 | F16: ='C3-4 - Bank-2'!G17 -> 50000 | G16: H / 3 / 2
B18: DETAILS OF OUTSTANDING CHEQUES | F18: =E26 -> 0
B20: Date | C20: Particulars | D20: Cheque No. | E20: Amount (£) | G20: IRIS CODE
C26: TOTAL | E26: =SUBTOTAL(9,E21:E24) -> 0
B28: Closing Balance as per Accounts | E28: =E13 -> 45260 | F28: =F16-F18 -> 50000
B35: Bank Book Details
B37: Opening Balance as per Accounts | E37: =B9 -> 44783 | F37: 0 | G37: H / 3 / 3
B38: ADJUSTMENTS IF ANY
A40: ADD: | B40: RECEIPTS | F40: ='Barclays Bank Ac -30470120'!G1708 -> 598113.09
A42: LESS: | B42: PAYMENTS | F42: ='Barclays Bank Ac -30470120'!F1708 -> 554080.66
B45: CLOSING BALANCE AS PER ACCOUNTS | E45: =B10 -> 45260 | F45: =F37+F40-F42 -> 44032.43 | G45: H / 3 / 2
D47: Difference | F47: =F28-F45 -> 5967.57

Sheet Barclays Bank Ac 50237620 (C)
A1: Client Name : | C1: =Info!C3 -> Forest Car Company Ltd | E1: Prepared by: | G1: =+Info!C8 -> Aratee
A2: File No. : | C2: =+'BRS Barclays Bank Ac -30470120'!C2 -> 7033 | D2: =+E8 -> 692 | E2: Date: | G2: =+Info!C9 -> 45343
A4: A/C Holder Name: | C4: =+'BRS Barclays Bank Ac -30470120'!C4 -> Forest Car Company Ltd | E4: Reviewed by: | G4: =+Info!C11 -> Mitesh
A5: Bank Name : | C5: =+'BRS Barclays Bank Ac -30470120'!C5 -> Barclays Bank | E5: Date: | G5: =+Info!C12 -> 45352
A6: Account No. : | C6: =+'BRS Barclays Bank Ac -30470120'!C6 -> 30470120
A7: =C5& " A/c # "&C6 -> Barclays Bank A/c # 30470120
A8: Period Start : | C8: =Info!C5 -> 44783 | E8: =+'BRS Barclays Bank Ac -30470120'!E8 -> 692
A9: Period End : | C9: =Info!C6 -> 45260
A11: Sr No | B11: Date | D11: Particulars | E11: IRIS | F11: Payments | G11: Receipts
A13: 1 | B13: 45232 | C13: Fund transfer | D13: 202519 30470120 MOBILE-CHANNEL FT | E13: 692 | G13: 50000 | H13: Barclays BankA/c. No.: 30470120
E15: 692 Total | G15: =SUBTOTAL(9,G13:G13) -> 50000
E17: Grand Total | G17: =SUBTOTAL(9,G12:G13) -> 50000

Sheet Journal
B2: Client : | C2: =Info!C3 -> Forest Car Company Ltd | E2: Prepared by : | F2: =Info!C8 -> Aratee | G2: Date : | H2: =Info!C9 -> 45343
B3: Y/E : | C3: =Info!C6 -> 45260 | E3: Reviewed by : | F3: =Info!C11 -> Mitesh | G3: Date : | H3: =Info!C12 -> 45352
B5: Journals
B7: Sr. No. | C7: AP code | D7: Particulars | E7: Debit (£) | F7: Credit (£)
B9: PROFIT/(Loss) as per Books Profit and loss account :
B11: 1 | C11: 727 | D11: =IF(F11<>""," To "&IF(C11="","",VLOOKUP(C11,ETB!$B$10:$C$678,2,0)),IF(C11="","",VLOOKUP(C11,ETB!$B$10:$C$678,2,0))) -> Director's current account | E11: 100
C12: 966 | D12: =IF(F12<>""," To "&IF(C12="","",VLOOKUP(C12,ETB!$B$10:$C$678,2,0)),IF(C12="","",VLOOKUP(C12,ETB!$B$10:$C$678,2,0))) -> To Called up share capital | F12: 100
D13: =IF(F13<>""," To "&IF(C13="","",VLOOKUP(C13,ETB!$B$10:$C$678,2,0)),IF(C13="","",VLOOKUP(C13,ETB!$B$10:$C$678,2,0)))
D14: (Being : Share capital introduce through DCA.)
B16: =+B11+1 -> 2 | C16: 586 | D16: =IF(F16<>""," To "&IF(C16="","",VLOOKUP(C16,ETB!$B$10:$C$678,2,0)),IF(C16="","",VLOOKUP(C16,ETB!$B$10:$C$678,2,0))) -> Trade debtors | E16: =Sales!N253 -> 640214
C17: 1 | D17: =IF(F17<>""," To "&IF(C17="","",VLOOKUP(C17,ETB!$B$10:$C$678,2,0)),IF(C17="","",VLOOKUP(C17,ETB!$B$10:$C$678,2,0))) -> To Sales | F17: =Sales!P253 -> 615407.63
C18: 735 | D18: =IF(F18<>""," To "&IF(C18="","",VLOOKUP(C18,ETB!$B$10:$C$678,2,0)),IF(C18="","",VLOOKUP(C18,ETB!$B$10:$C$678,2,0))) -> To VAT | F18: =Sales!O253 -> 24806.37
D20: (Being : Current year sales booked.)
B22: =+B16+1 -> 3 | C22: 390/13 | D22: =IF(F22<>""," To "&IF(C22="","",VLOOKUP(C22,ETB!$B$10:$C$678,2,0)),IF(C22="","",VLOOKUP(C22,ETB!$B$10:$C$678,2,0))) -> Depreciation of fixtures and fittings | E22: ='F4 - FAR'!J30 -> 89.85
C23: 390/15 | D23: =IF(F23<>""," To "&IF(C23="","",VLOOKUP(C23,ETB!$B$10:$C$678,2,0)),IF(C23="","",VLOOKUP(C23,ETB!$B$10:$C$678,2,0))) -> Depreciation of computer equipment | E23: ='F4 - FAR'!J54 -> 82.6665
C24: 524/22 | D24: =IF(F24<>""," To "&IF(C24="","",VLOOKUP(C24,ETB!$B$10:$C$678,2,0)),IF(C24="","",VLOOKUP(C24,ETB!$B$10:$C$678,2,0))) -> To Fixtures & fittings - Charge for year | F24: =E22 -> 89.85
C25: 526/22 | D25: =IF(F25<>""," To "&IF(C25="","",VLOOKUP(C25,ETB!$B$10:$C$678,2,0)),IF(C25="","",VLOOKUP(C25,ETB!$B$10:$C$678,2,0))) -> To Computer equipment - Charge for year | F25: =E23 -> 82.6665
D27: (Being : Depreciation @20% RBM booked for current year.)
B29: =+B22+1 -> 4 | C29: 254 | D29: =IF(F29<>""," To "&IF(C29="","",VLOOKUP(C29,ETB!$B$10:$C$678,2,0)),IF(C29="","",VLOOKUP(C29,ETB!$B$10:$C$678,2,0))) -> Director's remuneration | E29: =Payroll!C38 -> 11440
C30: 254 | D30: =IF(F30<>""," To "&IF(C30="","",VLOOKUP(C30,ETB!$B$10:$C$678,2,0)),IF(C30="","",VLOOKUP(C30,ETB!$B$10:$C$678,2,0))) -> Director's remuneration | E30: =Payroll!K38 -> 97.35 | G30: ER NI
C31: 755 | D31: =IF(F31<>""," To "&IF(C31="","",VLOOKUP(C31,ETB!$B$10:$C$678,2,0)),IF(C31="","",VLOOKUP(C31,ETB!$B$10:$C$678,2,0))) -> To Social Security and other tax | F31: =E30 -> 97.35 | G31: ER NI
C32: 727 | D32: =IF(F32<>""," To "&IF(C32="","",VLOOKUP(C32,ETB!$B$10:$C$678,2,0)),IF(C32="","",VLOOKUP(C32,ETB!$B$10:$C$678,2,0))) -> To Director's current account | F32: =Payroll!J38 -> 11440
D33: =IF(F33<>""," To "&IF(C33="","",VLOOKUP(C33,ETB!$B$10:$C$678,2,0)),IF(C33="","",VLOOKUP(C33,ETB!$B$10:$C$678,2,0)))
D34: (Being : Director's remuneration booked for current year.)
B36: =+B29+1 -> 5 | C36: 255 | D36: =IF(F36<>""," To "&IF(C36="","",VLOOKUP(C36,ETB!$B$10:$C$678,2,0)),IF(C36="","",VLOOKUP(C36,ETB!$B$10:$C$678,2,0))) -> Wages | E36: =Payroll!C70 -> 11440
C37: 738 | D37: =IF(F37<>""," To "&IF(C37="","",VLOOKUP(C37,ETB!$B$10:$C$678,2,0)),IF(C37="","",VLOOKUP(C37,ETB!$B$10:$C$678,2,0))) -> To Net Wages | F37: =E36 -> 11440
D38: =IF(F38<>""," To "&IF(C38="","",VLOOKUP(C38,ETB!$B$10:$C$678,2,0)),IF(C38="","",VLOOKUP(C38,ETB!$B$10:$C$678,2,0)))
D39: (Being : Wages booked for current year.)
B41: =B36+1 -> 6 | C41: 668 | D41: =IF(F41<>""," To "&IF(C41="","",VLOOKUP(C41,ETB!$B$10:$C$678,2,0)),IF(C41="","",VLOOKUP(C41,ETB!$B$10:$C$678,2,0))) -> Cash in hand | E41: =Sales!AE240 -> 71072.2
C42: 727 | D42: =IF(F42<>""," To "&IF(C42="","",VLOOKUP(C42,ETB!$B$10:$C$678,2,0)),IF(C42="","",VLOOKUP(C42,ETB!$B$10:$C$678,2,0))) -> Director's current account | E42: =Sales!AD240 -> 1300
C43: 586 | D43: =IF(F43<>""," To "&IF(C43="","",VLOOKUP(C43,ETB!$B$10:$C$678,2,0)),IF(C43="","",VLOOKUP(C43,ETB!$B$10:$C$678,2,0))) -> To Trade debtors | F43: =Sales!AD240+Sales!AE240 -> 72372.2
D45: (Being : Trade debtors adjusted through cash and DCA.)
B47: =B41+1 -> 7 | C47: 1 | D47: =IF(F47<>""," To "&IF(C47="","",VLOOKUP(C47,ETB!$B$10:$C$678,2,0)),IF(C47="","",VLOOKUP(C47,ETB!$B$10:$C$678,2,0))) -> Sales | E47: =Sales!Y264 -> 12906
C48: 586 | D48: =IF(F48<>""," To "&IF(C48="","",VLOOKUP(C48,ETB!$B$10:$C$678,2,0)),IF(C48="","",VLOOKUP(C48,ETB!$B$10:$C$678,2,0))) -> To Trade debtors | F48: =E47 -> 12906
D50: (Being : Reversal of sales booked.)
B52: =+B47+1 -> 8 | C52: 586 | D52: =IF(F52<>""," To "&IF(C52="","",VLOOKUP(C52,ETB!$B$10:$C$678,2,0)),IF(C52="","",VLOOKUP(C52,ETB!$B$10:$C$678,2,0))) -> Trade debtors | E52: =Sales!Y240 -> 300
C53: 92 | D53: =IF(F53<>""," To "&IF(C53="","",VLOOKUP(C53,ETB!$B$10:$C$678,2,0)),IF(C53="","",VLOOKUP(C53,ETB!$B$10:$C$678,2,0))) -> To Other income | F53: =E52 -> 300
D55: (Being : Additional income booked which is incurred during sales.)
B57: =+B52+1 -> 9 | C57: 755 | D57: =IF(F57<>""," To "&IF(C57="","",VLOOKUP(C57,ETB!$B$10:$C$678,2,0)),IF(C57="","",VLOOKUP(C57,ETB!$B$10:$C$678,2,0))) -> Social Security and other tax | E57: =-'C4-4 - PAYE-NI'!H45 -> 97.35
C58: 254 | D58: =IF(F58<>""," To "&IF(C58="","",VLOOKUP(C58,ETB!$B$10:$C$678,2,0)),IF(C58="","",VLOOKUP(C58,ETB!$B$10:$C$678,2,0))) -> To Director's remuneration | F58: =E57 -> 97.35
...

Sheet TB
B2: Client : | C2: =Index!C2 -> Forest Car Company Ltd | D2: Prepared by : | E2: =Info!C8 -> Aratee | F2: Date : | G2: =Index!J2 -> 45343
B3: Year end : | C3: =Index!C3 -> 45260 | D3: Reviewed by : | E3: =Info!C11 -> Mitesh | F3: Date : | G3: =Index!J3 -> 45352
B5: Trial Balance
B7: Tax calc | C7: NL Description | D7: Dr | E7: Cr
D122: =SUM(D8:D121) -> 0 | E122: =SUM(E8:E121) -> 0
D124: =E122-D122 -> 0

Sheet Opening TB
B2: Client : | C2: =Index!C2 -> Forest Car Company Ltd | D2: Prepared by : | E2: =Info!C8 -> Aratee | F2: Date : | G2: =Index!J2 -> 45343
B3: Year end : | C3: =Index!C3 -> 45260 | D3: Reviewed by : | E3: =Info!C11 -> Mitesh | F3: Date : | G3: =Index!J3 -> 45352
B5: Trial Balance
B7: N/C | C7: NL Description | D7: Dr | E7: Cr | G7: Check
G8: =VLOOKUP(B:B,ETB!B:B,1,) -> 0
G9: =VLOOKUP(B:B,ETB!B:B,1,) -> 0
G10: =VLOOKUP(B:B,ETB!B:B,1,) -> 0
G11: =VLOOKUP(B:B,ETB!B:B,1,) -> 0
G12: =VLOOKUP(B:B,ETB!B:B,1,) -> 0
G13: =VLOOKUP(B:B,ETB!B:B,1,) -> 0
G14: =VLOOKUP(B:B,ETB!B:B,1,) -> 0
G15: =VLOOKUP(B:B,ETB!B:B,1,) -> 0
G16: =VLOOKUP(B:B,ETB!B:B,1,) -> 0
G17: =VLOOKUP(B:B,ETB!B:B,1,) -> 0
G18: =VLOOKUP(B:B,ETB!B:B,1,) -> 0
G19: =VLOOKUP(B:B,ETB!B:B,1,) -> 0
... G89: =VLOOKUP(B:B,ETB!B:B,1,) -> 0
D92: =SUM(D8:D91) -> 0 | E92: =SUM(E8:E91) -> 0
D94: =E92-D92 -> 0

Sheet ETB
B2: Client : | C2: =Info!C3 -> Forest Car Company Ltd | L2: Prepared by : | M2: =Info!C8 -> Aratee | Q2: Date : | R2: =Info!C9 -> 45343
B3: Year end : | C3: =Info!C6 -> 45260 | L3: Reviewed by : | M3: =Info!C11 -> Mitesh | Q3: Date : | R3: =Info!C12 -> 45352
B5: Extended Trial Balance (ETB)
B6: =+D7 -> Opening Balance
B7: IRIS Code | C7: Name | D7: Opening Balance | F7: Barclays BankA/c. No.: 30470120 | H7: Barclays BankA/c. No.: 50237620 | J7: PDB | L7: Journals | N7: Finalisation Journal | Q7: Closing Balance | S7: IRIS Code
D8: Debit | E8: Credit | F8: Debit | G8: Credit | H8: Debit | I8: Credit | J8: Debit | K8: Credit | L8: Debit | M8: Credit | N8: Debit | O8: Credit | Q8: Debit | R8: Credit
B10: 502 | C10: Goodwill | D10: =SUMIF(TB!$B$9:$E$120,ETB!B10,TB!$D$9:$D$120) -> 0 | E10: =SUMIF(TB!$B$9:$E$120,ETB!B10,TB!$E$9:$E$120) -> 0 | L10: =SUMIF(Journal!$C$10:$C$304,ETB!B10,Journal!$E$10:$E$304) -> 0 | M10: =SUMIF(Journal!$C$10:$C$304,ETB!B10,Journal!$F$10:$F$304) -> 0 | Q10: =MAX((D10-E10+F10-G10+J10-K10+L10-M10+N10-O10),0) -> 0 | R10: =MAX((M10-L10+K10-J10+G10-F10+E10-D10+O10-N10),0) -> 0 | S10: =B10 -> 502 | U10: =+Q10-R10 -> 0
B11: 502/1 | C11: Goodwill Cost/valuation b/f | D11: =SUMIF(TB!$B$9:$E$120,ETB!B11,TB!$D$9:$D$120) -> 0 | E11: =SUMIF(TB!$B$9:$E$120,ETB!B11,TB!$E$9:$E$120) -> 0 | L11: =SUMIF(Journal!$C$10:$C$304,ETB!B11,Journal!$E$10:$E$304) -> 0 | M11: =SUMIF(Journal!$C$10:$C$304,ETB!B11,Journal!$F$10:$F$304) -> 0 | Q11: =MAX((D11-E11+F11-G11+J11-K11+L11-M11+N11-O11),0) -> 0 | R11: =MAX((M11-L11+K11-J11+G11-F11+E11-D11+O11-N11),0) -> 0 | S11: =B11 -> 502/1 | U11: =+Q11-R11 -> 0
B12: 502/2 | C12: Goodwill - Additions | D12: =SUMIF(TB!$B$9:$E$120,ETB!B12,TB!$D$9:$D$120) -> 0 | E12: =SUMIF(TB!$B$9:$E$120,ETB!B12,TB!$E$9:$E$120) -> 0 | L12: =SUMIF(Journal!$C$10:$C$304,ETB!B12,Journal!$E$10:$E$304) -> 0 | M12: =SUMIF(Journal!$C$10:$C$304,ETB!B12,Journal!$F$10:$F$304) -> 0 | Q12: =MAX((D12-E12+F12-G12+J12-K12+L12-M12+N12-O12),0) -> 0 | R12: =MAX((M12-L12+K12-J12+G12-F12+E12-D12+O12-N12),0) -> 0 | S12: =B12 -> 502/2 | U12: =+Q12-R12 -> 0
B13: 502/3 | C13: Goodwill - Disposals | D13: =SUMIF(TB!$B$9:$E$120,ETB!B13,TB!$D$9:$D$120) -> 0 | E13: =SUMIF(TB!$B$9:$E$120,ETB!B13,TB!$E$9:$E$120) -> 0 | L13: =SUMIF(Journal!$C$10:$C$304,ETB!B13,Journal!$E$10:$E$304) -> 0 | M13: =SUMIF(Journal!$C$10:$C$304,ETB!B13,Journal!$F$10:$F$304) -> 0 | Q13: =MAX((D13-E13+F13-G13+J13-K13+L13-M13+N13-O13),0) -> 0 | R13: =MAX((M13-L13+K13-J13+G13-F13+E13-D13+O13-N13),0) -> 0 | S13: =B13 -> 502/3 | U13: =+Q13-R13 -> 0
B14: 502/21 | C14: Goodwill - Amortisation b/fwd | D14: =SUMIF(TB!$B$9:$E$120,ETB!B14,TB!$D$9:$D$120) -> 0 | E14: =SUMIF(TB!$B$9:$E$120,ETB!B14,TB!$E$9:$E$120) -> 0 | L14: =SUMIF(Journal!$C$10:$C$304,ETB!B14,Journal!$E$10:$E$304) -> 0 | M14: =SUMIF(Journal!$C$10:$C$304,ETB!B14,Journal!$F$10:$F$304) -> 0 | Q14: =MAX((D14-E14+F14-G14+J14-K14+L14-M14+N14-O14),0) -> 0 | R14: =MAX((M14-L14+K14-J14+G14-F14+E14-D14+O14-N14),0) -> 0 | S14: =B14 -> 502/21 | U14: =+Q14-R14 -> 0
B15: 502/22 | C15: Goodwill - Charge for year | D15: =SUMIF(TB!$B$9:$E$120,ETB!B15,TB!$D$9:$D$120) -> 0 | E15: =SUMIF(TB!$B$9:$E$120,ETB!B15,TB!$E$9:$E$120) -> 0 | L15: =SUMIF(Journal!$C$10:$C$304,ETB!B15,Journal!$E$10:$E$304) -> 0 | M15: =SUMIF(Journal!$C$10:$C$304,ETB!B15,Journal!$F$10:$F$304) -> 0 | Q15: =MAX((D15-E15+F15-G15+J15-K15+L15-M15+N15-O15),0) -> 0 | R15: =MAX((M15-L15+K15-J15+G15-F15+E15-D15+O15-N15),0) -> 0 | S15: =B15 -> 502/22 | U15: =+Q15-R15 -> 0
B16: 502/23 | C16: Goodwill - Eliminated on disposals | D16: =SUMIF(TB!$B$9:$E$120,ETB!B16,TB!$D$9:$D$120) -> 0 | E16: =SUMIF(TB!$B$9:$E$120,ETB!B16,TB!$E$9:$E$120) -> 0 | L16: =SUMIF(Journal!$C$10:$C$304,ETB!B16,Journal!$E$10:$E$304) -> 0 | M16: =SUMIF(Journal!$C$10:$C$304,ETB!B16,Journal!$F$10:$F$304) -> 0 | Q16: =MAX((D16-E16+F16-G16+J16-K16+L16-M16+N16-O16),0) -> 0 | R16: =MAX((M16-L16+K16-J16+G16-F16+E16-D16+O16-N16),0) -> 0 | S16: =B16 -> 502/23 | U16: =+Q16-R16 -> 0
B17: 503 | C17: Patents & licences | D17: =SUMIF(TB!$B$9:$E$120,ETB!B17,TB!$D$9:$D$120) -> 0 | E17: =SUMIF(TB!$B$9:$E$120,ETB!B17,TB!$E$9:$E$120) -> 0 | L17: =SUMIF(Journal!$C$10:$C$304,ETB!B17,Journal!$E$10:$E$304) -> 0 | M17: =SUMIF(Journal!$C$10:$C$304,ETB!B17,Journal!$F$10:$F$304) -> 0 | Q17: =MAX((D17-E17+F17-G17+J17-K17+L17-M17+N17-O17),0) -> 0 | R17: =MAX((M17-L17+K17-J17+G17-F17+E17-D17+O17-N17),0) -> 0 | S17: =B17 -> 503 | U17: =+Q17-R17 -> 0
B18: 503/1 | C18: Patents & licences Cost/valuation b/f | D18: =SUMIF(TB!$B$9:$E$120,ETB!B18,TB!$D$9:$D$120) -> 0 | E18: =SUMIF(TB!$B$9:$E$120,ETB!B18,TB!$E$9:$E$120) -> 0 | L18: =SUMIF(Journal!$C$10:$C$304,ETB!B18,Journal!$E$10:$E$304) -> 0 | M18: =SUMIF(Journal!$C$10:$C$304,ETB!B18,Journal!$F$10:$F$304) -> 0 | Q18: =MAX((D18-E18+F18-G18+J18-K18+L18-M18+N18-O18),0) -> 0 | R18: =MAX((M18-L18+K18-J18+G18-F18+E18-D18+O18-N18),0) -> 0 | S18: =B18 -> 503/1 | U18: =+Q18-R18 -> 0
B19: 503/2 | C19: Patents & licences - additions | D19: =SUMIF(TB!$B$9:$E$120,ETB!B19,TB!$D$9:$D$120) -> 0 | E19: =SUMIF(TB!$B$9:$E$120,ETB!B19,TB!$E$9:$E$120) -> 0 | L19: =SUMIF(Journal!$C$10:$C$304,ETB!B19,Journal!$E$10:$E$304) -> 0 | M19: =SUMIF(Journal!$C$10:$C$304,ETB!B19,Journal!$F$10:$F$304) -> 0 | Q19: =MAX((D19-E19+F19-G19+J19-K19+L19-M19+N19-O19),0) -> 0 | R19: =MAX((M19-L19+K19-J19+G19-F19+E19-D19+O19-N19),0) -> 0 | S19: =B19 -> 503/2 | U19: =+Q19-R19 -> 0
B20: 503/3 | C20: Patents & licences - disposals | D20: =SUMIF(TB!$B$9:$E$120,ETB!B20,TB!$D$9:$D$120) -> 0 | E20: =SUMIF(TB!$B$9:$E$120,ETB!B20,TB!$E$9:$E$120) -> 0 | L20: =SUMIF(Journal!$C$10:$C$304,ETB!B20,Journal!$E$10:$E$304) -> 0 | M20: =SUMIF(Journal!$C$10:$C$304,ETB!B20,Journal!$F$10:$F$304) -> 0 | Q20: =MAX((D20-E20+F20-G20+J20-K20+L20-M20+N20-O20),0) -> 0 | R20: =MAX((M20-L20+K20-J20+G20-F20+E20-D20+O20-N20),0) -> 0 | S20: =B20 -> 503/3 | U20: =+Q20-R20 -> 0
B21: 503/21 | C21: Patents & licences - amortisation b/fwd | D21: =SUMIF(TB!$B$9:$E$120,ETB!B21,TB!$D$9:$D$120) -> 0 | E21: =SUMIF(TB!$B$9:$E$120,ETB!B21,TB!$E$9:$E$120) -> 0 | L21: =SUMIF(Journal!$C$10:$C$304,ETB!B21,Journal!$E$10:$E$304) -> 0 | M21: =SUMIF(Journal!$C$10:$C$304,ETB!B21,Journal!$F$10:$F$304) -> 0 | Q21: =MAX((D21-E21+F21-G21+J21-K21+L21-M21+N21-O21),0) -> 0 | R21: =MAX((M21-L21+K21-J21+G21-F21+E21-D21+O21-N21),0) -> 0 | S21: =B21 -> 503/21 | U21: =+Q21-R21 -> 0
B22: 503/22 | C22: Patents & licences - amortisation charge in year | D22: =SUMIF(TB!$B$9:$E$120,ETB!B22,TB!$D$9:$D$120) -> 0 | E22: =SUMIF(TB!$B$9:$E$120,ETB!B22,TB!$E$9:$E$120) -> 0 | L22: =SUMIF(Journal!$C$10:$C$304,ETB!B22,Journal!$E$10:$E$304) -> 0 | M22: =SUMIF(Journal!$C$10:$C$304,ETB!B22,Journal!$F$10:$F$304) -> 0 | Q22: =MAX((D22-E22+F22-G22+J22-K22+L22-M22+N22-O22),0) -> 0 | R22: =MAX((M22-L22+K22-J22+G22-F22+E22-D22+O22-N22),0) -> 0 | S22: =B22 -> 503/22 | U22: =+Q22-R22 -> 0
B23: 503/23 | C23: Patents & licences - depreciation on disposals | D23: =SUMIF(TB!$B$9:$E$120,ETB!B23,TB!$D$9:$D$120) -> 0 | E23: =SUMIF(TB!$B$9:$E$120,ETB!B23,TB!$E$9:$E$120) -> 0 | L23: =SUMIF(Journal!$C$10:$C$304,ETB!B23,Journal!$E$10:$E$304) -> 0 | M23: =SUMIF(Journal!$C$10:$C$304,ETB!B23,Journal!$F$10:$F$304) -> 0 | Q23: =MAX((D23-E23+F23-G23+J23-K23+L23-M23+N23-O23),0) -> 0 | R23: =MAX((M23-L23+K23-J23+G23-F23+E23-D23+O23-N23),0) -> 0 | S23: =B23 -> 503/23 | U23: =+Q23-R23 -> 0
B24: 504 | C24: Development Cost | D24: =SUMIF(TB!$B$9:$E$120,ETB!B24,TB!$D$9:$D$120) -> 0 | E24: =SUMIF(TB!$B$9:$E$120,ETB!B24,TB!$E$9:$E$120) -> 0 | L24: =SUMIF(Journal!$C$10:$C$304,ETB!B24,Journal!$E$10:$E$304) -> 0 | M24: =SUMIF(Journal!$C$10:$C$304,ETB!B24,Journal!$F$10:$F$304) -> 0 | Q24: =MAX((D24-E24+F24-G24+J24-K24+L24-M24+N24-O24),0) -> 0 | R24: =MAX((M24-L24+K24-J24+G24-F24+E24-D24+O24-N24),0) -> 0 | S24: =B24 -> 504 | U24: =+Q24-R24 -> 0
B25: 504/1 | C25: Development Cost/valuation b/f | D25: =SUMIF(TB!$B$9:$E$120,ETB!B25,TB!$D$9:$D$120) -> 0 | E25: =SUMIF(TB!$B$9:$E$120,ETB!B25,TB!$E$9:$E$120) -> 0 | L25: =SUMIF(Journal!$C$10:$C$304,ETB!B25,Journal!$E$10:$E$304) -> 0 | M25: =SUMIF(Journal!$C$10:$C$304,ETB!B25,Journal!$F$10:$F$304) -> 0 | Q25: =MAX((D25-E25+F25-G25+J25-K25+L25-M25+N25-O25),0) -> 0 | R25: =MAX((M25-L25+K25-J25+G25-F25+E25-D25+O25-N25),0) -> 0 | S25: =B25 -> 504/1 | U25: =+Q25-R25 -> 0
B26: 504/2 | C26: Development - additions | D26: =SUMIF(TB!$B$9:$E$120,ETB!B26,TB!$D$9:$D$120) -> 0 | E26: =SUMIF(TB!$B$9:$E$120,ETB!B26,TB!$E$9:$E$120) -> 0 | L26: =SUMIF(Journal!$C$10:$C$304,ETB!B26,Journal!$E$10:$E$304) -> 0 | M26: =SUMIF(Journal!$C$10:$C$304,ETB!B26,Journal!$F$10:$F$304) -> 0 | Q26: =MAX((D26-E26+F26-G26+J26-K26+L26-M26+N26-O26),0) -> 0 | R26: =MAX((M26-L26+K26-J26+G26-F26+E26-D26+O26-N26),0) -> 0 | S26: =B26 -> 504/2 | U26: =+Q26-R26 -> 0
B27: 504/3 | C27: Development - disposals | D27: =SUMIF(TB!$B$9:$E$120,ETB!B27,TB!$D$9:$D$120) -> 0 | E27: =SUMIF(TB!$B$9:$E$120,ETB!B27,TB!$E$9:$E$120) -> 0 | L27: =SUMIF(Journal!$C$10:$C$304,ETB!B27,Journal!$E$10:$E$304) -> 0 | M27: =SUMIF(Journal!$C$10:$C$304,ETB!B27,Journal!$F$10:$F$304) -> 0 | Q27: =MAX((D27-E27+F27-G27+J27-K27+L27-M27+N27-O27),0) -> 0 | R27: =MAX((M27-L27+K27-J27+G27-F27+E27-D27+O27-N27),0) -> 0 | S27: =B27 -> 504/3 | U27: =+Q27-R27 -> 0
B28: 504/21 | C28: Development - amortisation b/fwd | D28: =SUMIF(TB!$B$9:$E$120,ETB!B28,TB!$D$9:$D$120) -> 0 | E28: =SUMIF(TB!$B$9:$E$120,ETB!B28,TB!$E$9:$E$120) -> 0 | L28: =SUMIF(Journal!$C$10:$C$304,ETB!B28,Journal!$E$10:$E$304) -> 0 | M28: =SUMIF(Journal!$C$10:$C$304,ETB!B28,Journal!$F$10:$F$304) -> 0 | Q28: =MAX((D28-E28+F28-G28+J28-K28+L28-M28+N28-O28),0) -> 0 | R28: =MAX((M28-L28+K28-J28+G28-F28+E28-D28+O28-N28),0) -> 0 | S28: =B28 -> 504/21 | U28: =+Q28-R28 -> 0
B29: 505 | C29: Computer Software | D29: =SUMIF(TB!$B$9:$E$120,ETB!B29,TB!$D$9:$D$120) -> 0 | E29: =SUMIF(TB!$B$9:$E$120,ETB!B29,TB!$E$9:$E$120) -> 0 | L29: =SUMIF(Journal!$C$10:$C$304,ETB!B29,Journal!$E$10:$E$304) -> 0 | M29: =SUMIF(Journal!$C$10:$C$304,ETB!B29,Journal!$F$10:$F$304) -> 0 | Q29: =MAX((D29-E29+F29-G29+J29-K29+L29-M29+N29-O29),0) -> 0 | R29: =MAX((M29-L29+K29-J29+G29-F29+E29-D29+O29-N29),0) -> 0 | S29: =B29 -> 505 | U29: =+Q29-R29 -> 0
B30: 505/1 | C30: Computer Software Cost/valuation b/f | D30: =SUMIF(TB!$B$9:$E$120,ETB!B30,TB!$D$9:$D$120) -> 0 | E30: =SUMIF(TB!$B$9:$E$120,ETB!B30,TB!$E$9:$E$120) -> 0 | L30: =SUMIF(Journal!$C$10:$C$304,ETB!B30,Journal!$E$10:$E$304) -> 0 | M30: =SUMIF(Journal!$C$10:$C$304,ETB!B30,Journal!$F$10:$F$304) -> 0 | Q30: =MAX((D30-E30+F30-G30+J30-K30+L30-M30+N30-O30),0) -> 0 | R30: =MAX((M30-L30+K30-J30+G30-F30+E30-D30+O30-N30),0) -> 0 | S30: =B30 -> 505/1 | U30: =+Q30-R30 -> 0
B31: 505/2 | C31: Intellectual property - additions | D31: =SUMIF(TB!$B$9:$E$120,ETB!B31,TB!$D$9:$D$120) -> 0 | E31: =SUMIF(TB!$B$9:$E$120,ETB!B31,TB!$E$9:$E$120) -> 0 | L31: =SUMIF(Journal!$C$10:$C$304,ETB!B31,Journal!$E$10:$E$304) -> 0 | M31: =SUMIF(Journal!$C$10:$C$304,ETB!B31,Journal!$F$10:$F$304) -> 0 | Q31: =MAX((D31-E31+F31-G31+J31-K31+L31-M31+N31-O31),0) -> 0 | R31: =MAX((M31-L31+K31-J31+G31-F31+E31-D31+O31-N31),0) -> 0 | S31: =B31 -> 505/2 | U31: =+Q31-R31 -> 0
B32: 505/3 | C32: Intellectual property - disposals | D32: =SUMIF(TB!$B$9:$E$120,ETB!B32,TB!$D$9:$D$120) -> 0 | E32: =SUMIF(TB!$B$9:$E$120,ETB!B32,TB!$E$9:$E$120) -> 0 | L32: =SUMIF(Journal!$C$10:$C$304,ETB!B32,Journal!$E$10:$E$304) -> 0 | M32: =SUMIF(Journal!$C$10:$C$304,ETB!B32,Journal!$F$10:$F$304) -> 0 | Q32: =MAX((D32-E32+F32-G32+J32-K32+L32-M32+N32-O32),0) -> 0 | R32: =MAX((M32-L32+K32-J32+G32-F32+E32-D32+O32-N32),0) -> 0 | S32: =B32 -> 505/3 | U32: =+Q32-R32 -> 0
B33: 505/21 | C33: Intellectual property - amortisation b/fwd | D33: =SUMIF(TB!$B$9:$E$120,ETB!B33,TB!$D$9:$D$120) -> 0 | E33: =SUMIF(TB!$B$9:$E$120,ETB!B33,TB!$E$9:$E$120) -> 0 | L33: =SUMIF(Journal!$C$10:$C$304,ETB!B33,Journal!$E$10:$E$304) -> 0 | M33: =SUMIF(Journal!$C$10:$C$304,ETB!B33,Journal!$F$10:$F$304) -> 0 | Q33: =MAX((D33-E33+F33-G33+J33-K33+L33-M33+N33-O33),0) -> 0 | R33: =MAX((M33-L33+K33-J33+G33-F33+E33-D33+O33-N33),0) -> 0 | S33: =B33 -> 505/21 | U33: =+Q33-R33 -> 0
B34: 505/22 | C34: Intellectual property - amortisation charge in year | D34: =SUMIF(TB!$B$9:$E$120,ETB!B34,TB!$D$9:$D$120) -> 0 | E34: =SUMIF(TB!$B$9:$E$120,ETB!B34,TB!$E$9:$E$120) -> 0 | L34: =SUMIF(Journal!$C$10:$C$304,ETB!B34,Journal!$E$10:$E$304) -> 0 | M34: =SUMIF(Journal!$C$10:$C$304,ETB!B34,Journal!$F$10:$F$304) -> 0 | Q34: =MAX((D34-E34+F34-G34+J34-K34+L34-M34+N34-O34),0) -> 0 | R34: =MAX((M34-L34+K34-J34+G34-F34+E34-D34+O34-N34),0) -> 0 | S34: =B34 -> 505/22 | U34: =+Q34-R34 -> 0
B35: 505/23 | C35: Intellectual property - amortisation on disposals | D35: =SUMIF(TB!$B$9:$E$120,ETB!B35,TB!$D$9:$D$120) -> 0 | E35: =SUMIF(TB!$B$9:$E$120,ETB!B35,TB!$E$9:$E$120) -> 0 | L35: =SUMIF(Journal!$C$10:$C$304,ETB!B35,Journal!$E$10:$E$304) -> 0 | M35: =SUMIF(Journal!$C$10:$C$304,ETB!B35,Journal!$F$10:$F$304) -> 0 | Q35: =MAX((D35-E35+F35-G35+J35-K35+L35-M35+N35-O35),0) -> 0 | R35: =MAX((M35-L35+K35-J35+G35-F35+E35-D35+O35-N35),0) -> 0 | S35: =B35 -> 505/23 | U35: =+Q35-R35 -> 0
B36: 512 | C36: Freehold Property | D36: =SUMIF(TB!$B$9:$E$120,ETB!B36,TB!$D$9:$D$120) -> 0 | E36: =SUMIF(TB!$B$9:$E$120,ETB!B36,TB!$E$9:$E$120) -> 0 | L36: =SUMIF(Journal!$C$10:$C$304,ETB!B36,Journal!$E$10:$E$304) -> 0 | M36: =SUMIF(Journal!$C$10:$C$304,ETB!B36,Journal!$F$10:$F$304) -> 0 | Q36: =MAX((D36-E36+F36-G36+J36-K36+L36-M36+N36-O36),0) -> 0 | R36: =MAX((M36-L36+K36-J36+G36-F36+E36-D36+O36-N36),0) -> 0 | S36: =B36 -> 512 | U36: =+Q36-R36 -> 0
B37: 512/1 | C37: Freehold Property Cost/valuation b/f | D37: =SUMIF(TB!$B$9:$E$120,ETB!B37,TB!$D$9:$D$120) -> 0 | E37: =SUMIF(TB!$B$9:$E$120,ETB!B37,TB!$E$9:$E$120) -> 0 | L37: =SUMIF(Journal!$C$10:$C$304,ETB!B37,Journal!$E$10:$E$304) -> 0 | M37: =SUMIF(Journal!$C$10:$C$304,ETB!B37,Journal!$F$10:$F$304) -> 0 | Q37: =MAX((D37-E37+F37-G37+J37-K37+L37-M37+N37-O37),0) -> 0 | R37: =MAX((M37-L37+K37-J37+G37-F37+E37-D37+O37-N37),0) -> 0 | S37: =B37 -> 512/1 | U37: =+Q37-R37 -> 0
B38: 512/2 | C38: Freehold Property - Additions | D38: =SUMIF(TB!$B$9:$E$120,ETB!B38,TB!$D$9:$D$120) -> 0 | E38: =SUMIF(TB!$B$9:$E$120,ETB!B38,TB!$E$9:$E$120) -> 0 | L38: =SUMIF(Journal!$C$10:$C$304,ETB!B38,Journal!$E$10:$E$304) -> 0 | M38: =SUMIF(Journal!$C$10:$C$304,ETB!B38,Journal!$F$10:$F$304) -> 0 | Q38: =MAX((D38-E38+F38-G38+J38-K38+L38-M38+N38-O38),0) -> 0 | R38: =MAX((M38-L38+K38-J38+G38-F38+E38-D38+O38-N38),0) -> 0 | S38: =B38 -> 512/2 | U38: =+Q38-R38 -> 0
B39: 512/3 | C39: Freehold Property - Disposals | D39: =SUMIF(TB!$B$9:$E$120,ETB!B39,TB!$D$9:$D$120) -> 0 | E39: =SUMIF(TB!$B$9:$E$120,ETB!B39,TB!$E$9:$E$120) -> 0 | L39: =SUMIF(Journal!$C$10:$C$304,ETB!B39,Journal!$E$10:$E$304) -> 0 | M39: =SUMIF(Journal!$C$10:$C$304,ETB!B39,Journal!$F$10:$F$304) -> 0 | Q39: =MAX((D39-E39+F39-G39+J39-K39+L39-M39+N39-O39),0) -> 0 | R39: =MAX((M39-L39+K39-J39+G39-F39+E39-D39+O39-N39),0) -> 0 | S39: =B39 -> 512/3 | U39: =+Q39-R39 -> 0
B40: 512/21 | C40: Freehold Property - Depreciation b/fwd | D40: =SUMIF(TB!$B$9:$E$120,ETB!B40,TB!$D$9:$D$120) -> 0 | E40: =SUMIF(TB!$B$9:$E$120,ETB!B40,TB!$E$9:$E$120) -> 0 | L40: =SUMIF(Journal!$C$10:$C$304,ETB!B40,Journal!$E$10:$E$304) -> 0 | M40: =SUMIF(Journal!$C$10:$C$304,ETB!B40,Journal!$F$10:$F$304) -> 0 | Q40: =MAX((D40-E40+F40-G40+J40-K40+L40-M40+N40-O40),0) -> 0 | R40: =MAX((M40-L40+K40-J40+G40-F40+E40-D40+O40-N40),0) -> 0 | S40: =B40 -> 512/21 | U40: =+Q40-R40 -> 0
